Using TensorFlow backend.
Can't open '/etc/abrt/plugins/python.conf': No such file or directory
Traceback (most recent call last):
  File "trainAudio1.py", line 50, in <module>
    model.add(Conv2D(64, (15, 15)))
  File "/usr/lib64/python2.7/site-packages/keras/models.py", line 466, in add
    output_tensor = layer(self.outputs[0])
  File "/usr/lib64/python2.7/site-packages/keras/engine/topology.py", line 585, in __call__
    output = self.call(inputs, **kwargs)
  File "/usr/lib64/python2.7/site-packages/keras/layers/convolutional.py", line 164, in call
    dilation_rate=self.dilation_rate)
  File "/usr/lib64/python2.7/site-packages/keras/backend/tensorflow_backend.py", line 3095, in conv2d
    data_format='NHWC')
  File "/usr/lib/python2.7/site-packages/tensorflow/python/ops/nn_ops.py", line 661, in convolution
    op=op)
  File "/usr/lib/python2.7/site-packages/tensorflow/python/ops/nn_ops.py", line 331, in with_space_to_batch
    return op(input, num_spatial_dims, padding)
  File "/usr/lib/python2.7/site-packages/tensorflow/python/ops/nn_ops.py", line 653, in op
    name=name)
  File "/usr/lib/python2.7/site-packages/tensorflow/python/ops/nn_ops.py", line 129, in _non_atrous_convolution
    name=name)
  File "/usr/lib/python2.7/site-packages/tensorflow/python/ops/gen_nn_ops.py", line 403, in conv2d
    data_format=data_format, name=name)
  File "/usr/lib/python2.7/site-packages/tensorflow/python/framework/op_def_library.py", line 768, in apply_op
    op_def=op_def)
  File "/usr/lib/python2.7/site-packages/tensorflow/python/framework/ops.py", line 2338, in create_op
    set_shapes_for_outputs(ret)
  File "/usr/lib/python2.7/site-packages/tensorflow/python/framework/ops.py", line 1719, in set_shapes_for_outputs
    shapes = shape_func(op)
  File "/usr/lib/python2.7/site-packages/tensorflow/python/framework/ops.py", line 1669, in call_with_requiring
    return call_cpp_shape_fn(op, require_shape_fn=True)
  File "/usr/lib/python2.7/site-packages/tensorflow/python/framework/common_shapes.py", line 610, in call_cpp_shape_fn
    debug_python_shape_fn, require_shape_fn)
  File "/usr/lib/python2.7/site-packages/tensorflow/python/framework/common_shapes.py", line 676, in _call_cpp_shape_fn_impl
    raise ValueError(err.message)
ValueError: Negative dimension size caused by subtracting 15 from 7 for 'conv2d_8/convolution' (op: 'Conv2D') with input shapes: [?,7,8,64], [15,15,64,64].
